Workbook

Sheet Data Central
A3: 360 Brass | J3: 1018 Steel | N3: Slope | O3: =(M23-M20)/(N23-N20) -> 461334.34 | Q3: T3 Aluminum | X3: Cast Iron
A4: Specimen properties : Diameter | B4: 8.5852 | C4: mm | D4: Slope | E4: =(D32-D29)/(E32-E29) -> 66402.409 | J4: Specimen properties : Diameter | K4: 8.7376 | L4: mm | Q4: Specimen properties : Diameter | R4: 8.636 | S4: mm | T4: Slope | U4: =(T29-T26)/(U29-U26) -> 86168.737 | X4: Specimen properties : Diameter | Y4: 8.5598 | Z4: mm | AB4: Slope | AC4: =(AA23-AA21)/(AB23-AB21) -> 136861.25
A5: Strain : Axial Video gauge length | B5: 53.1665 | C5: mm | J5: Strain : Axial Video gauge length | K5: 51.9605 | L5: mm | Q5: Strain : Axial Video gauge length | R5: 49.70675 | S5: mm | X5: Strain : Axial Video gauge length | Y5: 50.9325 | Z5: mm
A6: Test : Rate 1 | B6: 5.08 | C6: mm/min | J6: Test : Rate 1 | K6: 5.08 | L6: mm/min | Q6: Test : Rate 1 | R6: 5.08 | S6: mm/min | X6: Test : Rate 1 | Y6: 5.08 | Z6: mm/min
A8: Load | B8: Extension from crosshead | C8: Extension from video extensotmer | D8: Stress | E8: Extensometer Strain | F8: Yield Stress | G8: 0.2% OFF | H8: True Stress | I8: True Strain | J8: Load | K8: Extension from crosshead | L8: Extension from video extensotmer | M8: Stress | N8: Strain | O8: Yield Stress | P8: 0.2% OFF | Q8: Load | R8: Extension from crosshead | S8: Extension from video extensotmer | T8: Stress | U8: Strain | V8: Yield Stress | W8: 0.2% OFF | X8: Load | Y8: Extension from crosshead | Z8: Extension from video extensotmer | AA8: Stress | AB8: Strain | AC8: Yield Stress | AD8: Yield Strain
A9: (N) | B9: (mm) | C9: (mm) | D9: MPa | J9: (N) | K9: (mm) | L9: (mm) | M9: MPa | Q9: (N) | R9: (mm) | S9: (mm) | T9: MPa | X9: (N) | Y9: (mm) | Z9: (mm) | AA9: MPa
A10: -1.43944 | B10: 0.00735 | C10: 0 | D10: =(A10/((PI()*($B$4*10^(-3))^2)/4))*10^(-6) -> -0.024865824 | E10: =C10/$B$5 -> 0 | F10: =E10*$E$4 -> 0 | G10: =E10+0.002 -> 0.002 | H10: =D10*(1+E10) -> -0.024865824 | I10: =LN(1+E10) -> 0 | J10: -1.79018 | K10: 0.0067 | L10: 0.00075 | M10: =(J10/((PI()*($K$4*10^(-3))^2)/4))*10^(-6) -> -0.029855373 | N10: =L10/$K$5 -> 1.4434041e-05 | O10: =N10*$O$3 -> 6.6589188 | P10: =N10+0.002 -> 0.002014434 | Q10: -0.93126 | R10: 0.00765 | S10: -0.00025 | T10: =(Q10/((PI()*($R$4*10^(-3))^2)/4))*10^(-6) -> -0.015898487 | U10: =S10/$R$5 -> -5.029498e-06 | V10: =$U$4*U10 -> -0.43338549 | W10: =U10+0.002 -> 0.0019949705 | X10: -0.95546 | Y10: 0.00652 | Z10: -0.0015 | AA10: =(X10/((PI()*($Y$4*10^(-3))^2)/4))*10^(-6) -> -0.016603337 | AB10: =Z10/$Y$5 -> -2.9450744e-05 | AC10: =(AB10*$AC$4) -> -4.0306656 | AD10: =AB10+0.002 -> 0.0019705493
A11: 14.17797 | B11: 0.0104 | C11: 0 | D11: =(A11/((PI()*($B$4*10^(-3))^2)/4))*10^(-6) -> 0.24491949 | E11: =C11/$B$5 -> 0 | F11: =E11*$E$4 -> 0 | G11: =E11+0.002 -> 0.002 | H11: =D11*(1+E11) -> 0.24491949 | I11: =LN(1+E11) -> 0 | J11: 18.81524 | K11: 0.00969 | L11: 0.0005 | M11: =(J11/((PI()*($K$4*10^(-3))^2)/4))*10^(-6) -> 0.31378744 | N11: =L11/$K$5 -> 9.6226942e-06 | O11: =N11*$O$3 -> 4.4392792 | P11: =N11+0.002 -> 0.0020096227 | Q11: 7.58508 | R11: 0.01046 | S11: -0.00025 | T11: =(Q11/((PI()*($R$4*10^(-3))^2)/4))*10^(-6) -> 0.12949262 | U11: =S11/$R$5 -> -5.029498e-06 | V11: =$U$4*U11 -> -0.43338549 | W11: =U11+0.002 -> 0.0019949705 | X11: 15.55482 | Y11: 0.00945 | Z11: -0.001 | AA11: =(X11/((PI()*($Y$4*10^(-3))^2)/4))*10^(-6) -> 0.27030114 | AB11: =Z11/$Y$5 -> -1.9633829e-05 | AC11: =(AB11*$AC$4) -> -2.6871104 | AD11: =AB11+0.002 -> 0.0019803662
A12: 169.99091 | B12: 0.02045 | C12: 0.00075 | D12: =(A12/((PI()*($B$4*10^(-3))^2)/4))*10^(-6) -> 2.9365337 | E12: =C12/$B$5 -> 1.4106627e-05 | F12: =E12*$E$4 -> 0.93671404 | G12: =E12+0.002 -> 0.0020141066 | H12: =D12*(1+E12) -> 2.9365751 | I12: =LN(1+E12) -> 1.4106528e-05 | J12: 209.34059 | K12: 0.01961 | L12: 0.0005 | M12: =(J12/((PI()*($K$4*10^(-3))^2)/4))*10^(-6) -> 3.4912363 | N12: =L12/$K$5 -> 9.6226942e-06 | O12: =N12*$O$3 -> 4.4392792 | P12: =N12+0.002 -> 0.0020096227 | Q12: 135.02939 | R12: 0.02021 | S12: 0 | T12: =(Q12/((PI()*($R$4*10^(-3))^2)/4))*10^(-6) -> 2.3052241 | U12: =S12/$R$5 -> 0 | V12: =$U$4*U12 -> 0 | W12: =U12+0.002 -> 0.002 | X12: 185.72704 | Y12: 0.01931 | Z12: -0.00075 | AA12: =(X12/((PI()*($Y$4*10^(-3))^2)/4))*10^(-6) -> 3.2274388 | AB12: =Z12/$Y$5 -> -1.4725372e-05 | AC12: =(AB12*$AC$4) -> -2.0153328 | AD12: =AB12+0.002 -> 0.0019852746
A13: 341.65128 | B13: 0.03091 | C13: 0.00225 | D13: =(A13/((PI()*($B$4*10^(-3))^2)/4))*10^(-6) -> 5.9019067 | E13: =C13/$B$5 -> 4.2319882e-05 | F13: =E13*$E$4 -> 2.8101421 | G13: =E13+0.002 -> 0.0020423199 | H13: =D13*(1+E13) -> 5.9021564 | I13: =LN(1+E13) -> 4.2318986e-05 | J13: 425.68842 | K13: 0.03007 | L13: 0.0005 | M13: =(J13/((PI()*($K$4*10^(-3))^2)/4))*10^(-6) -> 7.0993345 | N13: =L13/$K$5 -> 9.6226942e-06 | O13: =N13*$O$3 -> 4.4392792 | P13: =N13+0.002 -> 0.0020096227 | Q13: 290.26758 | R13: 0.03079 | S13: 0.00125 | T13: =(Q13/((PI()*($R$4*10^(-3))^2)/4))*10^(-6) -> 4.9554533 | U13: =S13/$R$5 -> 2.514749e-05 | V13: =$U$4*U13 -> 2.1669274 | W13: =U13+0.002 -> 0.0020251475 | X13: 386.33942 | Y13: 0.02983 | Z13: 0.0005 | AA13: =(X13/((PI()*($Y$4*10^(-3))^2)/4))*10^(-6) -> 6.713545 | AB13: =Z13/$Y$5 -> 9.8169145e-06 | AC13: =(AB13*$AC$4) -> 1.3435552 | AD13: =AB13+0.002 -> 0.0020098169
A14: 500.0799 | B14: 0.04042 | C14: 0.00575 | D14: =(A14/((PI()*($B$4*10^(-3))^2)/4))*10^(-6) -> 8.6387058 | E14: =C14/$B$5 -> 0.00010815081 | F14: =E14*$E$4 -> 7.1814743 | G14: =E14+0.002 -> 0.0021081508 | H14: =D14*(1+E14) -> 8.6396401 | I14: =LN(1+E14) -> 0.00010814496 | J14: 625.75537 | K14: 0.03982 | L14: 0.0005 | M14: =(J14/((PI()*($K$4*10^(-3))^2)/4))*10^(-6) -> 10.435911 | N14: =L14/$K$5 -> 9.6226942e-06 | O14: =N14*$O$3 -> 4.4392792 | P14: =N14+0.002 -> 0.0020096227 | Q14: 431.55826 | R14: 0.04054 | S14: 0.00525 | T14: =(Q14/((PI()*($R$4*10^(-3))^2)/4))*10^(-6) -> 7.3675702 | U14: =S14/$R$5 -> 0.00010561946 | V14: =$U$4*U14 -> 9.1010953 | W14: =U14+0.002 -> 0.0021056195 | X14: 568.25525 | Y14: 0.03952 | Z14: 0.002 | AA14: =(X14/((PI()*($Y$4*10^(-3))^2)/4))*10^(-6) -> 9.8747553 | AB14: =Z14/$Y$5 -> 3.9267658e-05 | AC14: =(AB14*$AC$4) -> 5.3742209 | AD14: =AB14+0.002 -> 0.0020392677
A15: 642.33838 | B15: 0.04945 | C15: 0.0065 | D15: =(A15/((PI()*($B$4*10^(-3))^2)/4))*10^(-6) -> 11.096171 | E15: =C15/$B$5 -> 0.00012225744 | F15: =E15*$E$4 -> 8.1181884 | G15: =E15+0.002 -> 0.0021222574 | H15: =D15*(1+E15) -> 11.097528 | I15: =LN(1+E15) -> 0.00012224996 | J15: 814.50732 | K15: 0.04879 | L15: 0.00075 | M15: =(J15/((PI()*($K$4*10^(-3))^2)/4))*10^(-6) -> 13.583785 | N15: =L15/$K$5 -> 1.4434041e-05 | O15: =N15*$O$3 -> 6.6589188 | P15: =N15+0.002 -> 0.002014434 | Q15: 561.1604 | R15: 0.04957 | S15: 0.006 | T15: =(Q15/((PI()*($R$4*10^(-3))^2)/4))*10^(-6) -> 9.5801403 | U15: =S15/$R$5 -> 0.00012070795 | V15: =$U$4*U15 -> 10.401252 | W15: =U15+0.002 -> 0.002120708 | X15: 735.1908 | Y15: 0.04855 | Z15: 0.00275 | AA15: =(X15/((PI()*($Y$4*10^(-3))^2)/4))*10^(-6) -> 12.775648 | AB15: =Z15/$Y$5 -> 5.399303e-05 | AC15: =(AB15*$AC$4) -> 7.3895537 | AD15: =AB15+0.002 -> 0.002053993
A16: 780.76685 | B16: 0.05812 | C16: 0.00825 | D16: =(A16/((PI()*($B$4*10^(-3))^2)/4))*10^(-6) -> 13.487475 | E16: =C16/$B$5 -> 0.0001551729 | F16: =E16*$E$4 -> 10.303854 | G16: =E16+0.002 -> 0.0021551729 | H16: =D16*(1+E16) -> 13.489568 | I16: =LN(1+E16) -> 0.00015516086 | J16: 994.91077 | K16: 0.05746 | L16: 0.0005 | M16: =(J16/((PI()*($K$4*10^(-3))^2)/4))*10^(-6) -> 16.592428 | N16: =L16/$K$5 -> 9.6226942e-06 | O16: =N16*$O$3 -> 4.4392792 | P16: =N16+0.002 -> 0.0020096227 | Q16: 686.21088 | R16: 0.05841 | S16: 0.00675 | T16: =(Q16/((PI()*($R$4*10^(-3))^2)/4))*10^(-6) -> 11.715004 | U16: =S16/$R$5 -> 0.00013579645 | V16: =$U$4*U16 -> 11.701408 | W16: =U16+0.002 -> 0.0021357964 | X16: 894.01556 | Y16: 0.05722 | Z16: 0.00375 | AA16: =(X16/((PI()*($Y$4*10^(-3))^2)/4))*10^(-6) -> 15.535598 | AB16: =Z16/$Y$5 -> 7.3626859e-05 | AC16: =(AB16*$AC$4) -> 10.076664 | AD16: =AB16+0.002 -> 0.0020736269
A17: 915.81146 | B17: 0.06667 | C17: 0.0095 | D17: =(A17/((PI()*($B$4*10^(-3))^2)/4))*10^(-6) -> 15.820323 | E17: =C17/$B$5 -> 0.00017868395 | F17: =E17*$E$4 -> 11.865045 | G17: =E17+0.002 -> 0.0021786839 | H17: =D17*(1+E17) -> 15.82315 | I17: =LN(1+E17) -> 0.00017866798 | J17: 1174.0801 | K17: 0.06607 | L17: 0.00125 | M17: =(J17/((PI()*($K$4*10^(-3))^2)/4))*10^(-6) -> 19.580488 | N17: =L17/$K$5 -> 2.4056735e-05 | O17: =N17*$O$3 -> 11.098198 | P17: =N17+0.002 -> 0.0020240567 | Q17: 807.66595 | R17: 0.06696 | S17: 0.01025 | T17: =(Q17/((PI()*($R$4*10^(-3))^2)/4))*10^(-6) -> 13.788487 | U17: =S17/$R$5 -> 0.00020620942 | V17: =$U$4*U17 -> 17.768805 | W17: =U17+0.002 -> 0.0022062094 | X17: 1049.5731 | Y17: 0.06571 | Z17: 0.0045 | AA17: =(X17/((PI()*($Y$4*10^(-3))^2)/4))*10^(-6) -> 18.238772 | AB17: =Z17/$Y$5 -> 8.8352231e-05 | AC17: =(AB17*$AC$4) -> 12.091997 | AD17: =AB17+0.002 -> 0.0020883522
A18: 1046.0083 | B18: 0.07527 | C18: 0.01025 | D18: =(A18/((PI()*($B$4*10^(-3))^2)/4))*10^(-6) -> 18.069428 | E18: =C18/$B$5 -> 0.00019279057 | F18: =E18*$E$4 -> 12.801759 | G18: =E18+0.002 -> 0.0021927906 | H18: =D18*(1+E18) -> 18.072912 | I18: =LN(1+E18) -> 0.00019277199 | J18: 1352.11 | K18: 0.07444 | L18: 0.001 | M18: =(J18/((PI()*($K$4*10^(-3))^2)/4))*10^(-6) -> 22.549547 | N18: =L18/$K$5 -> 1.9245388e-05 | O18: =N18*$O$3 -> 8.8785584 | P18: =N18+0.002 -> 0.0020192454 | Q18: 926.24982 | R18: 0.07539 | S18: 0.0115 | T18: =(Q18/((PI()*($R$4*10^(-3))^2)/4))*10^(-6) -> 15.812953 | U18: =S18/$R$5 -> 0.00023135691 | V18: =$U$4*U18 -> 19.935732 | W18: =U18+0.002 -> 0.0022313569 | X18: 1202.6709 | Y18: 0.07426 | Z18: 0.00475 | AA18: =(X18/((PI()*($Y$4*10^(-3))^2)/4))*10^(-6) -> 20.899201 | AB18: =Z18/$Y$5 -> 9.3260688e-05 | AC18: =(AB18*$AC$4) -> 12.763775 | AD18: =AB18+0.002 -> 0.0020932607
A19: 1168.748 | B19: 0.08371 | C19: 0.011 | D19: =(A19/((PI()*($B$4*10^(-3))^2)/4))*10^(-6) -> 20.189715 | E19: =C19/$B$5 -> 0.0002068972 | F19: =E19*$E$4 -> 13.738473 | G19: =E19+0.002 -> 0.0022068972 | H19: =D19*(1+E19) -> 20.193892 | I19: =LN(1+E19) -> 0.0002068758 | J19: 1531.5317 | K19: 0.08299 | L19: 0.00075 | M19: =(J19/((PI()*($K$4*10^(-3))^2)/4))*10^(-6) -> 25.541818 | N19: =L19/$K$5 -> 1.4434041e-05 | O19: =N19*$O$3 -> 6.6589188 | P19: =N19+0.002 -> 0.002014434 | Q19: 1042.7644 | R19: 0.084 | S19: 0.01325 | T19: =(Q19/((PI()*($R$4*10^(-3))^2)/4))*10^(-6) -> 17.802092 | U19: =S19/$R$5 -> 0.00026656339 | V19: =$U$4*U19 -> 22.969431 | W19: =U19+0.002 -> 0.0022665634 | X19: 1353.1578 | Y19: 0.08281 | Z19: 0.00475 | AA19: =(X19/((PI()*($Y$4*10^(-3))^2)/4))*10^(-6) -> 23.514261 | AB19: =Z19/$Y$5 -> 9.3260688e-05 | AC19: =(AB19*$AC$4) -> 12.763775 | AD19: =AB19+0.002 -> 0.0020932607
A20: 1284.5155 | B20: 0.09214 | C20: 0.0115 | D20: =(A20/((PI()*($B$4*10^(-3))^2)/4))*10^(-6) -> 22.189557 | E20: =C20/$B$5 -> 0.00021630162 | F20: =E20*$E$4 -> 14.362949 | G20: =E20+0.002 -> 0.0022163016 | H20: =D20*(1+E20) -> 22.194357 | I20: =LN(1+E20) -> 0.00021627823 | J20: 1711.615 | K20: 0.09154 | L20: 0.00075 | M20: =(J20/((PI()*($K$4*10^(-3))^2)/4))*10^(-6) -> 28.545121 | N20: =L20/$K$5 -> 1.4434041e-05 | O20: =N20*$O$3 -> 6.6589188 | P20: =N20+0.002 -> 0.002014434 | Q20: 1157.9082 | R20: 0.09243 | S20: 0.01475 | T20: =(Q20/((PI()*($R$4*10^(-3))^2)/4))*10^(-6) -> 19.767829 | U20: =S20/$R$5 -> 0.00029674038 | V20: =$U$4*U20 -> 25.569744 | W20: =U20+0.002 -> 0.0022967404 | X20: 1498.5413 | Y20: 0.0913 | Z20: 0.0065 | AA20: =(X20/((PI()*($Y$4*10^(-3))^2)/4))*10^(-6) -> 26.040636 | AB20: =Z20/$Y$5 -> 0.00012761989 | AC20: =(AB20*$AC$4) -> 17.466218 | AD20: =AB20+0.002 -> 0.0021276199
A21: 1400.3686 | B21: 0.10069 | C21: 0.012 | D21: =(A21/((PI()*($B$4*10^(-3))^2)/4))*10^(-6) -> 24.19088 | E21: =C21/$B$5 -> 0.00022570604 | F21: =E21*$E$4 -> 14.987425 | G21: =E21+0.002 -> 0.002225706 | H21: =D21*(1+E21) -> 24.19634 | I21: =LN(1+E21) -> 0.00022568057 | J21: 1891.7633 | K21: 0.10003 | L21: 0.00125 | M21: =(J21/((PI()*($K$4*10^(-3))^2)/4))*10^(-6) -> 31.549509 | N21: =L21/$K$5 -> 2.4056735e-05 | O21: =N21*$O$3 -> 11.098198 | P21: =N21+0.002 -> 0.0020240567 | Q21: 1267.1262 | R21: 0.10086 | S21: 0.01575 | T21: =(Q21/((PI()*($R$4*10^(-3))^2)/4))*10^(-6) -> 21.632401 | U21: =S21/$R$5 -> 0.00031685837 | V21: =$U$4*U21 -> 27.303286 | W21: =U21+0.002 -> 0.0023168584 | X21: 1637.4385 | Y21: 0.09973 | Z21: 0.007 | AA21: =(X21/((PI()*($Y$4*10^(-3))^2)/4))*10^(-6) -> 28.454298 | AB21: =Z21/$Y$5 -> 0.0001374368 | AC21: =(AB21*$AC$4) -> 18.809773 | AD21: =AB21+0.002 -> 0.0021374368
... A259: 16988.922 | B259: 2.11571 | C259: 0.49775 | D259: =(A259/((PI()*($B$4*10^(-3))^2)/4))*10^(-6) -> 293.4777 | E259: =C259/$B$5 -> 0.0093620983 | F259: =E259*$E$4 -> 621.66589 | G259: =E259+0.002 -> 0.011362098 | H259: =D259*(1+E259) -> 296.22527 | I259: =LN(1+E259) -> 0.0093185455 | J259: 27596.895 | K259: 2.11511 | L259: 0.09525 | M259: =(J259/((PI()*($K$4*10^(-3))^2)/4))*10^(-6) -> 460.24175 | N259: =L259/$K$5 -> 0.0018331232 | O259: =N259*$O$3 -> 845.68269 | P259: =N259+0.002 -> 0.0038331232 | Q259: 16586.039 | R259: 2.11595 | S259: 0.3745 | T259: =(Q259/((PI()*($R$4*10^(-3))^2)/4))*10^(-6) -> 283.15715 | U259: =S259/$R$5 -> 0.007534188 | V259: =$U$4*U259 -> 649.21146 | W259: =U259+0.002 -> 0.009534188 | X259: 20004.318 | Y259: 2.11481 | Z259: 0.44175 | AA259: =(X259/((PI()*($Y$4*10^(-3))^2)/4))*10^(-6) -> 347.62151 | AB259: =Z259/$Y$5 -> 0.008673244 | AC259: =(AB259*$AC$4) -> 1187.031 | AD259: =AB259+0.002 -> 0.010673244
A260: 17006.648 | B260: 2.1242 | C260: 0.50175 | D260: =(A260/((PI()*($B$4*10^(-3))^2)/4))*10^(-6) -> 293.78392 | E260: =C260/$B$5 -> 0.0094373337 | F260: =E260*$E$4 -> 626.66169 | G260: =E260+0.002 -> 0.011437334 | H260: =D260*(1+E260) -> 296.55646 | I260: =LN(1+E260) -> 0.0093930802 | J260: 27695.09 | K260: 2.12348 | L260: 0.09525 | M260: =(J260/((PI()*($K$4*10^(-3))^2)/4))*10^(-6) -> 461.87938 | N260: =L260/$K$5 -> 0.0018331232 | O260: =N260*$O$3 -> 845.68269 | P260: =N260+0.002 -> 0.0038331232 | Q260: 16604.598 | R260: 2.12432 | S260: 0.379 | T260: =(Q260/((PI()*($R$4*10^(-3))^2)/4))*10^(-6) -> 283.47398 | U260: =S260/$R$5 -> 0.007624719 | V260: =$U$4*U260 -> 657.0124 | W260: =U260+0.002 -> 0.009624719
A261: 17022.359 | B261: 2.13257 | C261: 0.50625 | D261: =(A261/((PI()*($B$4*10^(-3))^2)/4))*10^(-6) -> 294.05532 | E261: =C261/$B$5 -> 0.0095219734 | F261: =E261*$E$4 -> 632.28198 | G261: =E261+0.002 -> 0.011521973 | H261: =D261*(1+E261) -> 296.85531 | I261: =LN(1+E261) -> 0.0094769252 | J261: 27796.4 | K261: 2.13191 | L261: 0.09525 | M261: =(J261/((PI()*($K$4*10^(-3))^2)/4))*10^(-6) -> 463.56897 | N261: =L261/$K$5 -> 0.0018331232 | O261: =N261*$O$3 -> 845.68269 | P261: =N261+0.002 -> 0.0038331232 | Q261: 16622.98 | R261: 2.13287 | S261: 0.384 | T261: =(Q261/((PI()*($R$4*10^(-3))^2)/4))*10^(-6) -> 283.78782 | U261: =S261/$R$5 -> 0.0077253089 | V261: =$U$4*U261 -> 665.68011 | W261: =U261+0.002 -> 0.0097253089
A262: 17040.723 | B262: 2.141 | C262: 0.511 | D262: =(A262/((PI()*($B$4*10^(-3))^2)/4))*10^(-6) -> 294.37254 | E262: =C262/$B$5 -> 0.0096113154 | F262: =E262*$E$4 -> 638.2145 | G262: =E262+0.002 -> 0.011611315 | H262: =D262*(1+E262) -> 297.20185 | I262: =LN(1+E262) -> 0.0095654205 | J262: 27898.082 | K262: 2.14046 | L262: 0.0955 | M262: =(J262/((PI()*($K$4*10^(-3))^2)/4))*10^(-6) -> 465.26475 | N262: =L262/$K$5 -> 0.0018379346 | O262: =N262*$O$3 -> 847.90233 | P262: =N262+0.002 -> 0.0038379346 | Q262: 16640.148 | R262: 2.14142 | S262: 0.38975 | T262: =(Q262/((PI()*($R$4*10^(-3))^2)/4))*10^(-6) -> 284.08091 | U262: =S262/$R$5 -> 0.0078409874 | V262: =$U$4*U262 -> 675.64798 | W262: =U262+0.002 -> 0.0098409874
A263: 17058.217 | B263: 2.14955 | C263: 0.51625 | D263: =(A263/((PI()*($B$4*10^(-3))^2)/4))*10^(-6) -> 294.67474 | E263: =C263/$B$5 -> 0.0097100618 | F263: =E263*$E$4 -> 644.7715 | G263: =E263+0.002 -> 0.011710062 | H263: =D263*(1+E263) -> 297.53605 | I263: =LN(1+E263) -> 0.0096632221 | J263: 27995.842 | K263: 2.14883 | L263: 0.09525 | M263: =(J263/((PI()*($K$4*10^(-3))^2)/4))*10^(-6) -> 466.89512 | N263: =L263/$K$5 -> 0.0018331232 | O263: =N263*$O$3 -> 845.68269 | P263: =N263+0.002 -> 0.0038331232 | Q263: 16656.854 | R263: 2.14985 | S263: 0.3935 | T263: =(Q263/((PI()*($R$4*10^(-3))^2)/4))*10^(-6) -> 284.3661 | U263: =S263/$R$5 -> 0.0079164299 | V263: =$U$4*U263 -> 682.14876 | W263: =U263+0.002 -> 0.0099164299
A264: 17075.326 | B264: 2.15804 | C264: 0.5215 | D264: =(A264/((PI()*($B$4*10^(-3))^2)/4))*10^(-6) -> 294.9703 | E264: =C264/$B$5 -> 0.0098088082 | F264: =E264*$E$4 -> 651.3285 | G264: =E264+0.002 -> 0.011808808 | H264: =D264*(1+E264) -> 297.86361 | I264: =LN(1+E264) -> 0.0097610141 | J264: 28094.023 | K264: 2.15732 | L264: 0.09575 | M264: =(J264/((PI()*($K$4*10^(-3))^2)/4))*10^(-6) -> 468.53252 | N264: =L264/$K$5 -> 0.0018427459 | O264: =N264*$O$3 -> 850.12197 | P264: =N264+0.002 -> 0.0038427459 | Q264: 16674.316 | R264: 2.15828 | S264: 0.398 | T264: =(Q264/((PI()*($R$4*10^(-3))^2)/4))*10^(-6) -> 284.66422 | U264: =S264/$R$5 -> 0.0080069608 | V264: =$U$4*U264 -> 689.9497 | W264: =U264+0.002 -> 0.010006961
A265: 17090.867 | B265: 2.16647 | C265: 0.528 | D265: =(A265/((PI()*($B$4*10^(-3))^2)/4))*10^(-6) -> 295.23877 | E265: =C265/$B$5 -> 0.0099310656 | F265: =E265*$E$4 -> 659.44668 | G265: =E265+0.002 -> 0.011931066 | H265: =D265*(1+E265) -> 298.1708 | I265: =LN(1+E265) -> 0.0098820767 | J265: 28195.246 | K265: 2.16581 | L265: 0.096 | M265: =(J265/((PI()*($K$4*10^(-3))^2)/4))*10^(-6) -> 470.22064 | N265: =L265/$K$5 -> 0.0018475573 | O265: =N265*$O$3 -> 852.34161 | P265: =N265+0.002 -> 0.0038475573 | Q265: 16690.779 | R265: 2.16671 | S265: 0.4025 | T265: =(Q265/((PI()*($R$4*10^(-3))^2)/4))*10^(-6) -> 284.94528 | U265: =S265/$R$5 -> 0.0080974918 | V265: =$U$4*U265 -> 697.75064 | W265: =U265+0.002 -> 0.010097492
A266: 17104.939 | B266: 2.17502 | C266: 0.53225 | D266: =(A266/((PI()*($B$4*10^(-3))^2)/4))*10^(-6) -> 295.48186 | E266: =C266/$B$5 -> 0.010011003 | F266: =E266*$E$4 -> 664.75473 | G266: =E266+0.002 -> 0.012011003 | H266: =D266*(1+E266) -> 298.43993 | I266: =LN(1+E266) -> 0.009961225 | J266: 28297.496 | K266: 2.17424 | L266: 0.0965 | M266: =(J266/((PI()*($K$4*10^(-3))^2)/4))*10^(-6) -> 471.9259 | N266: =L266/$K$5 -> 0.00185718 | O266: =N266*$O$3 -> 856.78089 | P266: =N266+0.002 -> 0.00385718 | Q266: 16707.445 | R266: 2.17508 | S266: 0.407 | T266: =(Q266/((PI()*($R$4*10^(-3))^2)/4))*10^(-6) -> 285.2298 | U266: =S266/$R$5 -> 0.0081880228 | V266: =$U$4*U266 -> 705.55158 | W266: =U266+0.002 -> 0.010188023
A267: 17121.723 | B267: 2.18339 | C267: 0.537 | D267: =(A267/((PI()*($B$4*10^(-3))^2)/4))*10^(-6) -> 295.77179 | E267: =C267/$B$5 -> 0.010100345 | F267: =E267*$E$4 -> 670.68725 | G267: =E267+0.002 -> 0.012100345 | H267: =D267*(1+E267) -> 298.75918 | I267: =LN(1+E267) -> 0.010049678 | J267: 28396.826 | K267: 2.18273 | L267: 0.0965 | M267: =(J267/((PI()*($K$4*10^(-3))^2)/4))*10^(-6) -> 473.58245 | N267: =L267/$K$5 -> 0.00185718 | O267: =N267*$O$3 -> 856.78089 | P267: =N267+0.002 -> 0.00385718 | Q267: 16723.859 | R267: 2.18369 | S267: 0.41125 | T267: =(Q267/((PI()*($R$4*10^(-3))^2)/4))*10^(-6) -> 285.51002 | U267: =S267/$R$5 -> 0.0082735242 | V267: =$U$4*U267 -> 712.91913 | W267: =U267+0.002 -> 0.010273524
A268: 17137.83 | B268: 2.19182 | C268: 0.54175 | D268: =(A268/((PI()*($B$4*10^(-3))^2)/4))*10^(-6) -> 296.05004 | E268: =C268/$B$5 -> 0.010189687 | F268: =E268*$E$4 -> 676.61978 | G268: =E268+0.002 -> 0.012189687 | H268: =D268*(1+E268) -> 299.06669 | I268: =LN(1+E268) -> 0.010138122 | J268: 28498.074 | K268: 2.19123 | L268: 0.0975 | M268: =(J268/((PI()*($K$4*10^(-3))^2)/4))*10^(-6) -> 475.271 | N268: =L268/$K$5 -> 0.0018764254 | O268: =N268*$O$3 -> 865.65945 | P268: =N268+0.002 -> 0.0038764254 | Q268: 16738.961 | R268: 2.19218 | S268: 0.41575 | T268: =(Q268/((PI()*($R$4*10^(-3))^2)/4))*10^(-6) -> 285.76784 | U268: =S268/$R$5 -> 0.0083640552 | V268: =$U$4*U268 -> 720.72007 | W268: =U268+0.002 -> 0.010364055
A269: 17152.812 | B269: 2.20037 | C269: 0.54625 | D269: =(A269/((PI()*($B$4*10^(-3))^2)/4))*10^(-6) -> 296.30885 | E269: =C269/$B$5 -> 0.010274327 | F269: =E269*$E$4 -> 682.24006 | G269: =E269+0.002 -> 0.012274327 | H269: =D269*(1+E269) -> 299.35323 | I269: =LN(1+E269) -> 0.010221905 | J269: 28598.57 | K269: 2.19972 | L269: 0.09825 | M269: =(J269/((PI()*($K$4*10^(-3))^2)/4))*10^(-6) -> 476.947 | N269: =L269/$K$5 -> 0.0018908594 | O269: =N269*$O$3 -> 872.31837 | P269: =N269+0.002 -> 0.0038908594 | Q269: 16755.236 | R269: 2.20061 | S269: 0.42075 | T269: =(Q269/((PI()*($R$4*10^(-3))^2)/4))*10^(-6) -> 286.04569 | U269: =S269/$R$5 -> 0.0084646451 | V269: =$U$4*U269 -> 729.38778 | W269: =U269+0.002 -> 0.010464645
A270: 17168.545 | B270: 2.20886 | C270: 0.55075 | D270: =(A270/((PI()*($B$4*10^(-3))^2)/4))*10^(-6) -> 296.58062 | E270: =C270/$B$5 -> 0.010358967 | F270: =E270*$E$4 -> 687.86034 | G270: =E270+0.002 -> 0.012358967 | H270: =D270*(1+E270) -> 299.65289 | I270: =LN(1+E270) -> 0.01030568 | J270: 28696.754 | K270: 2.20815 | L270: 0.09975 | M270: =(J270/((PI()*($K$4*10^(-3))^2)/4))*10^(-6) -> 478.58444 | N270: =L270/$K$5 -> 0.0019197275 | O270: =N270*$O$3 -> 885.63621 | P270: =N270+0.002 -> 0.0039197275 | Q270: 16769.156 | R270: 2.2091 | S270: 0.42575 | T270: =(Q270/((PI()*($R$4*10^(-3))^2)/4))*10^(-6) -> 286.28333 | U270: =S270/$R$5 -> 0.0085652351 | V270: =$U$4*U270 -> 738.05549 | W270: =U270+0.002 -> 0.010565235
A271: 17182.887 | B271: 2.21729 | C271: 0.55575 | D271: =(A271/((PI()*($B$4*10^(-3))^2)/4))*10^(-6) -> 296.82837 | E271: =C271/$B$5 -> 0.010453011 | F271: =E271*$E$4 -> 694.1051 | G271: =E271+0.002 -> 0.012453011 | H271: =D271*(1+E271) -> 299.93112 | I271: =LN(1+E271) -> 0.010398756 | J271: 28794.857 | K271: 2.21652 | L271: 0.10125 | M271: =(J271/((PI()*($K$4*10^(-3))^2)/4))*10^(-6) -> 480.22054 | N271: =L271/$K$5 -> 0.0019485956 | O271: =N271*$O$3 -> 898.95404 | P271: =N271+0.002 -> 0.0039485956 | Q271: 16785.117 | R271: 2.21753 | S271: 0.43025 | T271: =(Q271/((PI()*($R$4*10^(-3))^2)/4))*10^(-6) -> 286.55582 | U271: =S271/$R$5 -> 0.0086557661 | V271: =$U$4*U271 -> 745.85643 | W271: =U271+0.002 -> 0.010655766
... A909: 20429.959 | B909: 7.61891 | C909: 3.884 | D909: =(A909/((PI()*($B$4*10^(-3))^2)/4))*10^(-6) -> 352.92041 | E909: =C909/$B$5 -> 0.073053521 | F909: =E909*$E$4 -> 4850.9298 | G909: =E909+0.002 -> 0.075053521 | H909: =D909*(1+E909) -> 378.70249 | I909: =LN(1+E909) -> 0.070508342 | J909: 26160.684 | K909: 7.61856 | L909: 4.801 | M909: =(J909/((PI()*($K$4*10^(-3))^2)/4))*10^(-6) -> 436.28963 | N909: =L909/$K$5 -> 0.092397109 | O909: =N909*$O$3 -> 42625.959 | P909: =N909+0.002 -> 0.094397109 | Q909: 20055.33 | R909: 7.61933 | S909: 3.6505 | T909: =(Q909/((PI()*($R$4*10^(-3))^2)/4))*10^(-6) -> 342.38495 | U909: =S909/$R$5 -> 0.07344073 | V909: =$U$4*U909 -> 6328.2949 | W909: =U909+0.002 -> 0.07544073
A910: 20433.562 | B910: 7.62752 | C910: 3.88825 | D910: =(A910/((PI()*($B$4*10^(-3))^2)/4))*10^(-6) -> 352.98266 | E910: =C910/$B$5 -> 0.073133458 | F910: =E910*$E$4 -> 4856.2378 | G910: =E910+0.002 -> 0.075133458 | H910: =D910*(1+E910) -> 378.79751 | I910: =LN(1+E910) -> 0.070582834 | Q910: 20056.455 | R910: 7.62776 | S910: 3.6565 | T910: =(Q910/((PI()*($R$4*10^(-3))^2)/4))*10^(-6) -> 342.40416 | U910: =S910/$R$5 -> 0.073561438 | V910: =$U$4*U910 -> 6338.6962 | W910: =U910+0.002 -> 0.075561438
A911: 20436.117 | B911: 7.63602 | C911: 3.8915 | D911: =(A911/((PI()*($B$4*10^(-3))^2)/4))*10^(-6) -> 353.02679 | E911: =C911/$B$5 -> 0.073194587 | F911: =E911*$E$4 -> 4860.2969 | G911: =E911+0.002 -> 0.075194587 | H911: =D911*(1+E911) -> 378.86644 | I911: =LN(1+E911) -> 0.070639796 | Q911: 20059.742 | R911: 7.63625 | S911: 3.662 | T911: =(Q911/((PI()*($R$4*10^(-3))^2)/4))*10^(-6) -> 342.46027 | U911: =S911/$R$5 -> 0.073672087 | V911: =$U$4*U911 -> 6348.2306 | W911: =U911+0.002 -> 0.075672087
A912: 20437.402 | B912: 7.64444 | C912: 3.89675 | D912: =(A912/((PI()*($B$4*10^(-3))^2)/4))*10^(-6) -> 353.049 | E912: =C912/$B$5 -> 0.073293333 | F912: =E912*$E$4 -> 4866.8539 | G912: =E912+0.002 -> 0.075293333 | H912: =D912*(1+E912) -> 378.92513 | I912: =LN(1+E912) -> 0.070731803 | Q912: 20059.877 | R912: 7.64468 | S912: 3.66725 | T912: =(Q912/((PI()*($R$4*10^(-3))^2)/4))*10^(-6) -> 342.46257 | U912: =S912/$R$5 -> 0.073777706 | V912: =$U$4*U912 -> 6357.3317 | W912: =U912+0.002 -> 0.075777706
A913: 20441.254 | B913: 7.65288 | C913: 3.90125 | D913: =(A913/((PI()*($B$4*10^(-3))^2)/4))*10^(-6) -> 353.11553 | E913: =C913/$B$5 -> 0.073377973 | F913: =E913*$E$4 -> 4872.4742 | G913: =E913+0.002 -> 0.075377973 | H913: =D913*(1+E913) -> 379.02643 | I913: =LN(1+E913) -> 0.07081066 | Q913: 20061.65 | R913: 7.65311 | S913: 3.67275 | T913: =(Q913/((PI()*($R$4*10^(-3))^2)/4))*10^(-6) -> 342.49285 | U913: =S913/$R$5 -> 0.073888355 | V913: =$U$4*U913 -> 6366.8662 | W913: =U913+0.002 -> 0.075888355
A914: 20446.293 | B914: 7.66137 | C914: 3.906 | D914: =(A914/((PI()*($B$4*10^(-3))^2)/4))*10^(-6) -> 353.20258 | E914: =C914/$B$5 -> 0.073467315 | F914: =E914*$E$4 -> 4878.4067 | G914: =E914+0.002 -> 0.075467315 | H914: =D914*(1+E914) -> 379.15142 | I914: =LN(1+E914) -> 0.070893891 | Q914: 20063.225 | R914: 7.66173 | S914: 3.67875 | T914: =(Q914/((PI()*($R$4*10^(-3))^2)/4))*10^(-6) -> 342.51972 | U914: =S914/$R$5 -> 0.074009063 | V914: =$U$4*U914 -> 6377.2675 | W914: =U914+0.002 -> 0.076009063
A915: 20446.824 | B915: 7.6698 | C915: 3.91125 | D915: =(A915/((PI()*($B$4*10^(-3))^2)/4))*10^(-6) -> 353.21175 | E915: =C915/$B$5 -> 0.073566061 | F915: =E915*$E$4 -> 4884.9637 | G915: =E915+0.002 -> 0.075566061 | H915: =D915*(1+E915) -> 379.19615 | I915: =LN(1+E915) -> 0.070985875 | Q915: 20063.084 | R915: 7.67009 | S915: 3.685 | T915: =(Q915/((PI()*($R$4*10^(-3))^2)/4))*10^(-6) -> 342.51732 | U915: =S915/$R$5 -> 0.074134801 | V915: =$U$4*U915 -> 6388.1021 | W915: =U915+0.002 -> 0.076134801
A916: 20449.387 | B916: 7.67829 | C916: 3.9165 | D916: =(A916/((PI()*($B$4*10^(-3))^2)/4))*10^(-6) -> 353.25602 | E916: =C916/$B$5 -> 0.073664808 | F916: =E916*$E$4 -> 4891.5207 | G916: =E916+0.002 -> 0.075664808 | H916: =D916*(1+E916) -> 379.27856 | I916: =LN(1+E916) -> 0.07107785 | Q916: 20065.799 | R916: 7.67853 | S916: 3.691 | T916: =(Q916/((PI()*($R$4*10^(-3))^2)/4))*10^(-6) -> 342.56367 | U916: =S916/$R$5 -> 0.074255509 | V916: =$U$4*U916 -> 6398.5034 | W916: =U916+0.002 -> 0.076255509
A917: 20454.264 | B917: 7.68678 | C917: 3.92175 | D917: =(A917/((PI()*($B$4*10^(-3))^2)/4))*10^(-6) -> 353.34027 | E917: =C917/$B$5 -> 0.073763554 | F917: =E917*$E$4 -> 4898.0777 | G917: =E917+0.002 -> 0.075763554 | H917: =D917*(1+E917) -> 379.4039 | I917: =LN(1+E917) -> 0.071169817 | Q917: 20070.414 | R917: 7.68708 | S917: 3.69725 | T917: =(Q917/((PI()*($R$4*10^(-3))^2)/4))*10^(-6) -> 342.64246 | U917: =S917/$R$5 -> 0.074381246 | V917: =$U$4*U917 -> 6409.338 | W917: =U917+0.002 -> 0.076381246
...

Sheet Properties Compare
C13: Modulus of Elasticity (MPa) | D13: Yield Strength (MPa) | E13: Tensile Strength (MPa) | F13: Ductility (%) | G13: Resilience
A14: Gray Iron | B14: Experiment | C14: 136.86 | D14: 266.6 | E14: 346.53 | F14: =(0.44175/'Data Central'!Y5)*100 -> 0.8673244 | G14: 0.666472
B15: Literature | C15: 62.1-1450 | D15: 344.738 | E15: 90-1650 | F15: .2-40
A16: 1018 Steel | B16: Experiment | C16: 461.33 | D16: 634.82 | E16: 682.43 | F16: =(4.801/'Data Central'!K5)*100 -> 9.2397109 | G16: 1.33
B17: Literature | C17: 200 | D17: 372.32 | E17: 440 | F17: 15
A18: T6 Aluminum | B18: Experiment | C18: 86.16 | D18: 271.73 | E18: 344.9 | F18: =(7.40675/'Data Central'!R5)*100 -> 14.900894 | G18: 0.996
B19: Literature | C19: 68.9 | D19: 275.79 | E19: 310 | F19: 17
A20: 360 Brass | B20: Experiment | C20: 66.4 | D20: 282.58 | E20: 389.7 | F20: =(15.36375/'Data Central'!B5)*100 -> 28.897426 | G20: 1.45
B21: Literature | C21: 97 | D21: 310.264 | E21: 338-469 | F21: 53

Sheet True Vs Eng.
C5: ln stress | D5: ln strain | G5: n | H5: 0.9194
C6: =LN('Data Central'!$H253) -> 5.6841045 | D6: =LN('Data Central'!$I2533) -> -1.5161741 | G6: k | H6: 1201.827505 MPa
C7: =LN('Data Central'!$H254) -> 5.6852811 | D7: =LN('Data Central'!$I2534) -> -1.5156412
C8: =LN('Data Central'!$H255) -> 5.6864423 | D8: =LN('Data Central'!$I2535) -> -1.5151258
C9: =LN('Data Central'!$H256) -> 5.6877672 | D9: =LN('Data Central'!$I2536) -> -1.5145765
C10: =LN('Data Central'!$H257) -> 5.6889281 | D10: =LN('Data Central'!$I2537) -> -1.5140446
C11: =LN('Data Central'!$H258) -> 5.690011 | D11: =LN('Data Central'!$I2538) -> -1.5134788
C12: =LN('Data Central'!$H259) -> 5.6911202 | D12: =LN('Data Central'!$I2539) -> -1.5129134
C13: =LN('Data Central'!$H260) -> 5.6922376 | D13: =LN('Data Central'!$I2540) -> -1.5122286
C14: =LN('Data Central'!$H261) -> 5.6932448 | D14: =LN('Data Central'!$I2541) -> -1.5117667
C15: =LN('Data Central'!$H262) -> 5.6944115 | D15: =LN('Data Central'!$I2542) -> -1.5112196
C16: =LN('Data Central'!$H263) -> 5.6955354 | D16: =LN('Data Central'!$I2543) -> -1.5106557
C17: =LN('Data Central'!$H264) -> 5.6966357 | D17: =LN('Data Central'!$I2544) -> -1.5100069
C18: =LN('Data Central'!$H265) -> 5.6976665 | D18: =LN('Data Central'!$I2545) -> -1.5093757
... C272: =LN('Data Central'!$H519) -> 5.8269582 | D272: =LN('Data Central'!$I2799) -> -1.3710245

Sheet Strain Hardening
B9: Cycle 1 | J9: Cycle 2
A10: Specimen properties : Diameter | B10: 8.6106 | C10: mm | I10: Specimen properties : Diameter | J10: 8.6106 | K10: mm
A11: Strain : Axial Video gauge length | B11: 50.76 | C11: mm | I11: Strain : Axial Video gauge length | J11: 51.97075 | K11: mm
A12: Test : Rate 1 | B12: 5.08 | C12: mm/min | I12: Test : Rate 1 | J12: 5.08 | K12: mm/min
A14: Load | B14: Extension from crosshead | C14: Extension from video extensotmer | I14: Load | J14: Extension from crosshead | K14: Extension from video extensotmer
A15: (N) | B15: (mm) | C15: (mm) | D15: Eng. Stress | E15: Eng. Strain | I15: (N) | J15: (mm) | K15: (mm) | L15: Eng. Stress | M15: Eng. Strain
A16: -0.97287 | B16: 0.00729 | C16: 0 | D16: 0 | E16: =C16/B$11 -> 0 | I16: -0.30461 | J16: 0.00813 | K16: 0.00075 | L16: 0 | M16: 0
A17: 20.56235 | B17: 0.01034 | C17: 0 | D17: =(A17/((PI()*($B$10*10^(-3))^2)/4))*10^(-6) -> 0.35311489 | E17: =C17/B$11 -> 0 | I17: 45.22407 | J17: 0.01196 | K17: 0.0005 | L17: =(I17/((PI()*($J$10*10^(-3))^2)/4))*10^(-6) -> 0.7766278 | M17: 0
A18: 222.87361 | B18: 0.02027 | C18: 0.00025 | D18: =(A18/((PI()*($B$10*10^(-3))^2)/4))*10^(-6) -> 3.8273831 | E18: =C18/B$11 -> 4.9251379e-06 | I18: 298.39633 | J18: 0.02093 | K18: 0.00075 | L18: =(I18/((PI()*($J$10*10^(-3))^2)/4))*10^(-6) -> 5.1243262 | M18: =K18/J$11 -> 1.4431194e-05
A19: 454.32715 | B19: 0.03067 | C19: 0.00075 | D19: =(A19/((PI()*($B$10*10^(-3))^2)/4))*10^(-6) -> 7.8021084 | E19: =C19/B$11 -> 1.4775414e-05 | I19: 550.37408 | J19: 0.02924 | K19: 0.00075 | L19: =(I19/((PI()*($J$10*10^(-3))^2)/4))*10^(-6) -> 9.4515114 | M19: =K19/J$11 -> 1.4431194e-05
A20: 666.74005 | B20: 0.04036 | C20: 0.0015 | D20: =(A20/((PI()*($B$10*10^(-3))^2)/4))*10^(-6) -> 11.449851 | E20: =C20/B$11 -> 2.9550827e-05 | I20: 804.91797 | J20: 0.03815 | K20: 0.00125 | L20: =(I20/((PI()*($J$10*10^(-3))^2)/4))*10^(-6) -> 13.822765 | M20: =K20/J$11 -> 2.4051991e-05
A21: 864.98212 | B21: 0.04945 | C21: 0.00225 | D21: =(A21/((PI()*($B$10*10^(-3))^2)/4))*10^(-6) -> 14.854239 | E21: =C21/B$11 -> 4.4326241e-05 | I21: 1053.0676 | J21: 0.04723 | K21: 0.00225 | L21: =(I21/((PI()*($J$10*10^(-3))^2)/4))*10^(-6) -> 18.08421 | M21: =K21/J$11 -> 4.3293583e-05
A22: 1051.4429 | B22: 0.05806 | C22: 0.00325 | D22: =(A22/((PI()*($B$10*10^(-3))^2)/4))*10^(-6) -> 18.056309 | E22: =C22/B$11 -> 6.4026793e-05 | I22: 1262.3289 | J22: 0.05596 | K22: 0.00325 | L22: =(I22/((PI()*($J$10*10^(-3))^2)/4))*10^(-6) -> 21.67783 | M22: =K22/J$11 -> 6.2535176e-05
A23: 1232.0654 | B23: 0.06655 | C23: 0.0035 | D23: =(A23/((PI()*($B$10*10^(-3))^2)/4))*10^(-6) -> 21.158119 | E23: =C23/B$11 -> 6.8951931e-05 | I23: 1428.0862 | J23: 0.06457 | K23: 0.00525 | L23: =(I23/((PI()*($J$10*10^(-3))^2)/4))*10^(-6) -> 24.524361 | M23: =K23/J$11 -> 0.00010101836
A24: 1414.8964 | B24: 0.07504 | C24: 0.004 | D24: =(A24/((PI()*($B$10*10^(-3))^2)/4))*10^(-6) -> 24.297854 | E24: =C24/B$11 -> 7.8802206e-05 | I24: 1594.6296 | J24: 0.073 | K24: 0.007 | L24: =(I24/((PI()*($J$10*10^(-3))^2)/4))*10^(-6) -> 27.384393 | M24: =K24/J$11 -> 0.00013469115
A25: 1596.8475 | B25: 0.08353 | C25: 0.00475 | D25: =(A25/((PI()*($B$10*10^(-3))^2)/4))*10^(-6) -> 27.422481 | E25: =C25/B$11 -> 9.357762e-05 | I25: 1768.3096 | J25: 0.08143 | K25: 0.00775 | L25: =(I25/((PI()*($J$10*10^(-3))^2)/4))*10^(-6) -> 30.366979 | M25: =K25/J$11 -> 0.00014912234
A26: 1774.7467 | B26: 0.09208 | C26: 0.0055 | D26: =(A26/((PI()*($B$10*10^(-3))^2)/4))*10^(-6) -> 30.477523 | E26: =C26/B$11 -> 0.00010835303 | I26: 1944.0112 | J26: 0.09004 | K26: 0.00925 | L26: =(I26/((PI()*($J$10*10^(-3))^2)/4))*10^(-6) -> 33.384283 | M26: =K26/J$11 -> 0.00017798473
A27: 1948.7609 | B27: 0.10057 | C27: 0.0065 | D27: =(A27/((PI()*($B$10*10^(-3))^2)/4))*10^(-6) -> 33.465848 | E27: =C27/B$11 -> 0.00012805359 | I27: 2119.9033 | J27: 0.09859 | K27: 0.0105 | L27: =(I27/((PI()*($J$10*10^(-3))^2)/4))*10^(-6) -> 36.404858 | M27: =K27/J$11 -> 0.00020203672
A28: 2106.4883 | B28: 0.109 | C28: 0.007 | D28: =(A28/((PI()*($B$10*10^(-3))^2)/4))*10^(-6) -> 36.174483 | E28: =C28/B$11 -> 0.00013790386 | I28: 2288.9534 | J28: 0.10696 | K28: 0.011 | L28: =(I28/((PI()*($J$10*10^(-3))^2)/4))*10^(-6) -> 39.307935 | M28: =K28/J$11 -> 0.00021165752
A29: 2250.3689 | B29: 0.11749 | C29: 0.00775 | D29: =(A29/((PI()*($B$10*10^(-3))^2)/4))*10^(-6) -> 38.645329 | E29: =C29/B$11 -> 0.00015267928 | I29: 2460.1973 | J29: 0.11545 | K29: 0.0115 | L29: =(I29/((PI()*($J$10*10^(-3))^2)/4))*10^(-6) -> 42.248687 | M29: =K29/J$11 -> 0.00022127832
... A544: 39956.863 | B544: 4.47136 | C544: 1.311 | D544: =(A544/((PI()*($B$10*10^(-3))^2)/4))*10^(-6) -> 686.17466 | E544: =C544/B$11 -> 0.025827423 | I544: 20059.525 | J544: 4.47578 | K544: 3.261 | L544: =(I544/((PI()*($J$10*10^(-3))^2)/4))*10^(-6) -> 344.47994 | M544: =K544/J$11 -> 0.062746834
I545: 20014.027 | J545: 4.48427 | K545: 3.271 | L545: =(I545/((PI()*($J$10*10^(-3))^2)/4))*10^(-6) -> 343.69861 | M545: =K545/J$11 -> 0.062939249
I546: 19970.006 | J546: 4.49276 | K546: 3.2805 | L546: =(I546/((PI()*($J$10*10^(-3))^2)/4))*10^(-6) -> 342.94264 | M546: =K546/J$11 -> 0.063122045
I547: 19923.66 | J547: 4.50119 | K547: 3.29025 | L547: =(I547/((PI()*($J$10*10^(-3))^2)/4))*10^(-6) -> 342.14675 | M547: =K547/J$11 -> 0.06330965
I548: 19876.891 | J548: 4.50962 | K548: 3.3 | L548: =(I548/((PI()*($J$10*10^(-3))^2)/4))*10^(-6) -> 341.34358 | M548: =K548/J$11 -> 0.063497256
I549: 19833.99 | J549: 4.51805 | K549: 3.3095 | L549: =(I549/((PI()*($J$10*10^(-3))^2)/4))*10^(-6) -> 340.60685 | M549: =K549/J$11 -> 0.063680051
I550: 19789.766 | J550: 4.52654 | K550: 3.319 | L550: =(I550/((PI()*($J$10*10^(-3))^2)/4))*10^(-6) -> 339.84739 | M550: =K550/J$11 -> 0.063862846
I551: 19744.102 | J551: 4.53515 | K551: 3.329 | L551: =(I551/((PI()*($J$10*10^(-3))^2)/4))*10^(-6) -> 339.06321 | M551: =K551/J$11 -> 0.064055262
I552: 19695.736 | J552: 4.54358 | K552: 3.339 | L552: =(I552/((PI()*($J$10*10^(-3))^2)/4))*10^(-6) -> 338.23264 | M552: =K552/J$11 -> 0.064247678
I553: 19646.713 | J553: 4.55195 | K553: 3.349 | L553: =(I553/((PI()*($J$10*10^(-3))^2)/4))*10^(-6) -> 337.39076 | M553: =K553/J$11 -> 0.064440094
I554: 19601.982 | J554: 4.5605 | K554: 3.359 | L554: =(I554/((PI()*($J$10*10^(-3))^2)/4))*10^(-6) -> 336.62261 | M554: =K554/J$11 -> 0.06463251
I555: 19556.129 | J555: 4.56887 | K555: 3.36875 | L555: =(I555/((PI()*($J$10*10^(-3))^2)/4))*10^(-6) -> 335.83517 | M555: =K555/J$11 -> 0.064820115
I556: 19509.621 | J556: 4.57742 | K556: 3.37875 | L556: =(I556/((PI()*($J$10*10^(-3))^2)/4))*10^(-6) -> 335.0365 | M556: =K556/J$11 -> 0.065012531
... I611: 16566.854 | J611: 5.04312 | K611: 3.93125 | L611: =(I611/((PI()*($J$10*10^(-3))^2)/4))*10^(-6) -> 284.50069 | M611: =K611/J$11 -> 0.075643511

Sheet Sheet1
A2: Specimen properties : Diameter | B2: 8.7376 | C2: mm
A3: Strain : Axial Video gauge length | B3: 51.9605 | C3: mm
A4: Test : Rate 1 | B4: 5.08 | C4: mm/min
A6: Load | B6: Extension from crosshead | C6: Extension from video extensotmer
A7: (N) | B7: (mm) | C7: (mm) | D7: Stress | E7: strain Ex | F7: Strain
A8: -1.79018 | B8: 0.0067 | C8: 0.00075 | D8: =(A8/((PI()*($B$2*10^(-3))^2)/4))*10^(-6) -> -0.029855373
A9: 18.81524 | B9: 0.00969 | C9: 0.0005 | D9: =(A9/((PI()*($B$2*10^(-3))^2)/4))*10^(-6) -> 0.31378744
A10: 209.34059 | B10: 0.01961 | C10: 0.0005 | D10: =(A10/((PI()*($B$2*10^(-3))^2)/4))*10^(-6) -> 3.4912363
A11: 425.68842 | B11: 0.03007 | C11: 0.0005 | D11: =(A11/((PI()*($B$2*10^(-3))^2)/4))*10^(-6) -> 7.0993345
A12: 625.75537 | B12: 0.03982 | C12: 0.0005 | D12: =(A12/((PI()*($B$2*10^(-3))^2)/4))*10^(-6) -> 10.435911
A13: 814.50732 | B13: 0.04879 | C13: 0.00075 | D13: =(A13/((PI()*($B$2*10^(-3))^2)/4))*10^(-6) -> 13.583785
A14: 994.91077 | B14: 0.05746 | C14: 0.0005 | D14: =(A14/((PI()*($B$2*10^(-3))^2)/4))*10^(-6) -> 16.592428
A15: 1174.0801 | B15: 0.06607 | C15: 0.00125 | D15: =(A15/((PI()*($B$2*10^(-3))^2)/4))*10^(-6) -> 19.580488
A16: 1352.11 | B16: 0.07444 | C16: 0.001 | D16: =(A16/((PI()*($B$2*10^(-3))^2)/4))*10^(-6) -> 22.549547
A17: 1531.5317 | B17: 0.08299 | C17: 0.00075 | D17: =(A17/((PI()*($B$2*10^(-3))^2)/4))*10^(-6) -> 25.541818
A18: 1711.615 | B18: 0.09154 | C18: 0.00075 | D18: =(A18/((PI()*($B$2*10^(-3))^2)/4))*10^(-6) -> 28.545121
A19: 1891.7633 | B19: 0.10003 | C19: 0.00125 | D19: =(A19/((PI()*($B$2*10^(-3))^2)/4))*10^(-6) -> 31.549509
... A907: 26160.684 | B907: 7.61856 | C907: 4.801 | D907: =(A907/((PI()*($B$2*10^(-3))^2)/4))*10^(-6) -> 436.28963
